<?xml version="1.0" encoding="utf-8"?>
<!-- =================================================================================== -->
<!-- |    This document was autogenerated by xacro from robot.xacro                    | -->
<!-- |    EDITING THIS FILE BY HAND IS NOT RECOMMENDED                                 | -->
<!-- =================================================================================== -->
<robot name="adamr2">
  <!-- base_footprint -->
  <link name="base_footprint"/>
  <joint name="base_link_joint" type="fixed">
    <origin xyz="0.0 0.0 0.262"/>
    <parent link="base_footprint"/>
    <child link="base_link"/>
  </joint>
  <link name="base_link">
    <visual>
      <origin xyz="0.0 0.0 0.0"/>
      <geometry>
        <mesh filename="package://adamr2_description/meshes/base_link.STL"/>
      </geometry>
      <material name="red">
        <color rgba="1.0 0.0 0.0 1.0"/>
      </material>
    </visual>
    <inertial>
      <origin xyz="0.0 0.0 0.0"/>
      <mass value="22.68"/>
      <inertia ixx="0.39" ixy="0.04" ixz="0.0" iyy="0.64" iyz="0.02" izz="0.70"/>
    </inertial>
    <collision>
      <origin xyz="0.0 0.0 0.0"/>
      <geometry>
        <box size="0.59 0.32 0.275"/>
      </geometry>
    </collision>
  </link>
  <joint name="left_wheel_joint" type="continuous">
    <origin xyz="0.0 0.1915 -0.1845"/>
    <parent link="base_link"/>
    <child link="left_wheel_link"/>
    <axis xyz="0 1 0"/>
  </joint>
  <link name="left_wheel_link">
    <visual>
      <origin rpy="0.0 0.0 0.0"/>
      <geometry>
        <mesh filename="package://adamr2_description/meshes/wheel_link.STL"/>
      </geometry>
      <material name="black">
        <color rgba="0.0 0.0 0.0 1.0"/>
      </material>
    </visual>
    <inertial>
      <origin xyz="0.0 0.0 0.0"/>
      <mass value="0.4"/>
      <inertia ixx="0.001" ixy="0.0" ixz="0.0" iyy="0.0006" iyz="0.0" izz="0.0006"/>
    </inertial>
    <collision>
      <origin rpy="1.57079632679 0.0 0.0" xyz="0.0 0.0 0.0"/>
      <geometry>
        <cylinder length="0.030" radius="0.0775"/>
      </geometry>
    </collision>
  </link>
  <transmission name="left_wheel_trans">
    <type>transmission_interface/SimpleTransmission</type>
    <joint name="left_wheel_joint">
      <hardwareInterface>hardware_interface/VelocityJointInterface</hardwareInterface>
    </joint>
    <actuator name="left_wheel_motor">
      <hardwareInterface>hardware_interface/VelocityJointInterface</hardwareInterface>
      <mechanicalReduction>1</mechanicalReduction>
    </actuator>
  </transmission>
  <joint name="right_wheel_joint" type="continuous">
    <origin xyz="0.0 -0.1915 -0.1845"/>
    <parent link="base_link"/>
    <child link="right_wheel_link"/>
    <axis xyz="0 1 0"/>
  </joint>
  <link name="right_wheel_link">
    <visual>
      <origin rpy="0.0 0.0 0.0"/>
      <geometry>
        <mesh filename="package://adamr2_description/meshes/wheel_link.STL"/>
      </geometry>
      <material name="black">
        <color rgba="0.0 0.0 0.0 1.0"/>
      </material>
    </visual>
    <inertial>
      <origin xyz="0.0 0.0 0.0"/>
      <mass value="0.4"/>
      <inertia ixx="0.001" ixy="0.0" ixz="0.0" iyy="0.0006" iyz="0.0" izz="0.0006"/>
    </inertial>
    <collision>
      <origin rpy="1.57079632679 0.0 0.0" xyz="0.0 0.0 0.0"/>
      <geometry>
        <cylinder length="0.030" radius="0.0775"/>
      </geometry>
    </collision>
  </link>
  <transmission name="right_wheel_trans">
    <type>transmission_interface/SimpleTransmission</type>
    <joint name="right_wheel_joint">
      <hardwareInterface>hardware_interface/VelocityJointInterface</hardwareInterface>
    </joint>
    <actuator name="right_wheel_motor">
      <hardwareInterface>hardware_interface/VelocityJointInterface</hardwareInterface>
      <mechanicalReduction>1</mechanicalReduction>
    </actuator>
  </transmission>
  <joint name="back_caster_support_joint" type="continuous">
    <origin xyz="-0.275 0.0 -0.1498"/>
    <parent link="base_link"/>
    <child link="back_caster_support_link"/>
    <axis xyz="0 0 1"/>
  </joint>
  <link name="back_caster_support_link">
    <visual>
      <origin rpy="0.0 0.0 0.0"/>
      <geometry>
        <mesh filename="package://adamr2_description/meshes/caster_link.STL"/>
      </geometry>
      <material name="red">
        <color rgba="0.0 0.0 0.0 1.0"/>
      </material>
    </visual>
    <inertial>
      <origin xyz="0.0 0.0 0.0"/>
      <mass value="0.3"/>
      <inertia ixx="1e-5" ixy="0.0" ixz="0.0" iyy="1e-5" iyz="0.0" izz="1e-5"/>
    </inertial>
  </link>
  <joint name="back_caster_wheel_joint" type="continuous">
    <origin rpy="0.0 0.0 0.0" xyz="-0.030 0.0 -0.072"/>
    <parent link="back_caster_support_link"/>
    <child link="back_caster_wheel_link"/>
    <axis xyz="0.0 1 0.0"/>
  </joint>
  <link name="back_caster_wheel_link">
    <inertial>
      <origin xyz="0.0 0.0 0.0"/>
      <mass value="0.17"/>
      <inertia ixx="1e-5" ixy="0.0" ixz="0.0" iyy="1e-5" iyz="0.0" izz="1e-5"/>
    </inertial>
    <collision>
      <origin rpy="1.57079632679 0.0 0.0" xyz="0.0 0.0 0.0"/>
      <geometry>
        <cylinder length="0.025" radius="0.0375"/>
      </geometry>
    </collision>
  </link>
  <joint name="front_caster_support_joint" type="continuous">
    <origin rpy="0 0 3.14159265359" xyz="0.275 0.0 -0.1498"/>
    <parent link="base_link"/>
    <child link="front_caster_support_link"/>
    <axis xyz="0 0 1"/>
  </joint>
  <link name="front_caster_support_link">
    <visual>
      <origin rpy="0.0 0.0 0.0"/>
      <geometry>
        <mesh filename="package://adamr2_description/meshes/caster_link.STL"/>
      </geometry>
      <material name="red">
        <color rgba="0.0 0.0 0.0 1.0"/>
      </material>
    </visual>
    <inertial>
      <origin xyz="0.0 0.0 0.0"/>
      <mass value="0.3"/>
      <inertia ixx="1e-5" ixy="0.0" ixz="0.0" iyy="1e-5" iyz="0.0" izz="1e-5"/>
    </inertial>
  </link>
  <joint name="front_caster_wheel_joint" type="continuous">
    <origin rpy="0.0 0.0 0.0" xyz="-0.030 0.0 -0.072"/>
    <parent link="front_caster_support_link"/>
    <child link="front_caster_wheel_link"/>
    <axis xyz="0.0 1 0.0"/>
  </joint>
  <link name="front_caster_wheel_link">
    <inertial>
      <origin xyz="0.0 0.0 0.0"/>
      <mass value="0.17"/>
      <inertia ixx="1e-5" ixy="0.0" ixz="0.0" iyy="1e-5" iyz="0.0" izz="1e-5"/>
    </inertial>
    <collision>
      <origin rpy="1.57079632679 0.0 0.0" xyz="0.0 0.0 0.0"/>
      <geometry>
        <cylinder length="0.025" radius="0.0375"/>
      </geometry>
    </collision>
  </link>
  <joint name="lidar_joint" type="fixed">
    <origin rpy="0 0 3.14159265359" xyz="0.275 0 0.177"/>
    <parent link="base_link"/>
    <child link="lidar_link"/>
  </joint>
  <link name="lidar_link">
    <visual>
      <geometry>
        <mesh filename="package://adamr2_description/meshes/lidar_link.STL"/>
      </geometry>
      <material name="blue">
        <color rgba="0.0 0.0 1.0 1.0"/>
      </material>
    </visual>
  </link>
</robot>

