<?xml version="1.0"?>
<robot xmlns:xacro="http://ros.org/wiki/xacro">
  <xacro:macro name="wheel" params="prefix parent *joint_origin *joint_axis">
    <joint name="${prefix}_wheel_joint" type="continuous">
      <xacro:insert_block name="joint_origin"/>
      <parent link="${parent}"/>
      <child link="${prefix}_wheel_link"/>
      <xacro:insert_block name="joint_axis"/>
    </joint>
    
    <link name="${prefix}_wheel_link">
      <visual>
        <origin rpy="${radians(90)} 0.0 0.0"/>
        <geometry>
          
        </geometry>
        <material name="black">
          <color rgba="0.0 0.0 0.0 1.0"/>
        </material>
      </visual>

      <inertial>
        <origin xyz="0.0 0.0 0.0"/>
        <mass value="0.4"/>
        <inertia ixx="0.001" ixy="0.0" ixz="0.0" iyy="0.0006" iyz="0.0" izz="0.0006"/>
      </inertial>

      <collision>
        <origin xyz="0.0 0.0 0.0" rpy="${radians(90)} 0.0 0.0"/>
        <geometry>
          <cylinder radius="0.0775" length="0.030"/>
        </geometry>
      </collision>
    </link>
  </xacro:macro>
</robot>